Workbook

Sheet 0 - Instructions
A1: How to Use This Workbook — SCGPC Fire Resistance Testing
A3: Sheet | B3: Purpose | C3: What to do
A4: 0 - Instructions | B4: Overview and guide | C4: Read thoroughly before commencing furnace heating or CTM strength tests.
A5: 1 - Mix Reference | B5: 12 Mix matrix: SCBA (0-25%), 4M & 6M NaOH | C5: Fill in 28-day ambient strength (MPa) once Batch 1 provides the values.
A6: 2 - Raw Data Entry | B6: Main data recording sheet (144 cubes) | C6: Fill YELLOW cells during/after testing (Pre/Post mass, CTM failure load). GREEN cells calculate automatically.
A7: 3 - Charts & Curves | B7: Visual analysis dashboard (Bar Charts & Curves) | C7: Dynamically generated Bar Charts and Residual Strength vs Temperature Curves placed before the Results summary.
A8: 4 - Residual Strength Summary | B8: Auto-summary table & residual strength % | C8: Fully automated — computes average post-fire MPa and residual % for all 12 mixes across 200–800°C.
A9: 5 - Mass Loss Summary | B9: Auto-summary table of thermal mass loss % | C9: Fully automated — computes average mass loss % across 200°C, 400°C, 600°C, and 800°C.
A10: 6 - Visual Observations Log | B10: Physical condition tracking (144 specimens) | C10: Fill post-fire visual observations: colour change, surface cracking, and spalling.
A11: 7 - Schedule & Checklist | B11: 3-Week testing schedule & QA checklist | C11: Track progress across Weeks 14–16 and verify critical laboratory safety checks.
A14: COLOR CONVENTIONS & CODING
A15: Yellow cells | B15: INPUT CELLS — Enter experimental lab data manually (mass, failure load, visual notes)
A16: Green cells | B16: AUTO-CALCULATED — Contains formulas; do not overwrite
A17: Blue headers | B17: STRUCTURE — Mix parameters, column headers, and structural categories
A18: Orange cells | B18: CRITICAL WARNING / KEY MIX — Important safety note or optimum candidate (M9)

Sheet 1 - Mix Reference
A1: SCGPC Fire Resistance Study — Mix Proportions & Reference Matrix
A2: 12 Mixes | Fly Ash : GGBS = 70:30 fixed | Na2SiO3 : NaOH = 1:1 fixed | SCBA Replacement: 0–25% | Molarities: 4M & 6M
A4: Mix ID | B4: SCBA (%) | C4: Molarity | D4: Remaining Binder (%) | E4: Fly Ash (%) [in Binder] | F4: GGBS (%) [in Binder] | G4: Series Category | H4: Mix Notes & Characteristics | I4: 28-Day Comp. Strength (MPa) [Batch 1 Input]
A5: M0 | B5: 0 | C5: 4M | D5: 100 | E5: 70 | F5: 30 | G5: 4M Series (Control) | H5: Baseline — 0% SCBA, FA:GGBS 70:30, 4M NaOH
A6: M1 | B6: 5 | C6: 4M | D6: 95 | E6: 66.5 | F6: 28.5 | G6: 4M Series | H6: 5% SCBA replacement
A7: M2 | B7: 10 | C7: 4M | D7: 90 | E7: 63 | F7: 27 | G7: 4M Series | H7: 10% SCBA replacement
A8: M3 | B8: 15 | C8: 4M | D8: 85 | E8: 59.5 | F8: 25.5 | G8: 4M Series | H8: 15% SCBA replacement
A9: M4 | B9: 20 | C9: 4M | D9: 80 | E9: 56 | F9: 24 | G9: 4M Series | H9: 20% SCBA replacement
A10: M5 | B10: 25 | C10: 4M | D10: 75 | E10: 52.5 | F10: 22.5 | G10: 4M Series | H10: 25% SCBA upper bound — watch workability
A11: M6 | B11: 0 | C11: 6M | D11: 100 | E11: 70 | F11: 30 | G11: 6M Series (Control) | H11: Baseline — 0% SCBA, FA:GGBS 70:30, 6M NaOH
A12: M7 | B12: 5 | C12: 6M | D12: 95 | E12: 66.5 | F12: 28.5 | G12: 6M Series | H12: 5% SCBA replacement
A13: M8 | B13: 10 | C13: 6M | D13: 90 | E13: 63 | F13: 27 | G13: 6M Series | H13: 10% SCBA replacement
A14: M9 | B14: 15 | C14: 6M | D14: 85 | E14: 59.5 | F14: 25.5 | G14: 6M Series (Key Mix) | H14: 15% SCBA — likely optimum mix
A15: M10 | B15: 20 | C15: 6M | D15: 80 | E15: 56 | F15: 24 | G15: 6M Series | H15: 20% SCBA replacement
A16: M11 | B16: 25 | C16: 6M | D16: 75 | E16: 52.5 | F16: 22.5 | G16: 6M Series | H16: 25% SCBA upper bound — watch workability

Sheet 2 - Raw Data Entry
A1: SCGPC Fire Resistance Testing — Raw Experimental Data Entry
A2: Fill YELLOW cells during laboratory testing. GREEN cells are computed automatically. Specimen size: 100mm cube (Area = 10,000 mm²).
A3: SPECIMEN IDENTIFICATION | D3: PRE-FIRE MEASUREMENTS | F3: POST-FIRE OBSERVATIONS | J3: CTM STRENGTH TESTING | M3: AUTO-CALCULATED RESULTS | P3: RECORDS
A4: Mix ID | B4: Temperature (°C) | C4: Replicate (1/2/3) | D4: Pre-Fire Mass (g) | E4: Pre-Fire Notes | F4: Post-Fire Mass (g) | G4: Colour Change | H4: Cracking (None/Min/Maj) | I4: Spalling (None/Part/Sev) | J4: Failure Load (kN) | K4: Failure Load (N) [auto] | L4: 28-Day Str. (MPa) [Ref] | M4: Mass Loss (%) [auto] | N4: Residual Strength (MPa) [auto] | O4: Residual Strength (%) [auto] | P4: Photo Filename
A5: M0 | B5: 200 | C5: 1 | K5: =IF(J5="","",J5*1000) | L5: =IF('1 - Mix Reference'!I5="","",'1 - Mix Reference'!I5) | M5: =IF(OR(D5="",F5=""),"",((D5-F5)/D5)*100) | N5: =IF(K5="","",K5/10000) | O5: =IF(OR(N5="",L5="",L5=0),"",(N5/L5)*100)
A6: M0 | B6: 200 | C6: 2 | K6: =IF(J6="","",J6*1000) | L6: =IF('1 - Mix Reference'!I5="","",'1 - Mix Reference'!I5) | M6: =IF(OR(D6="",F6=""),"",((D6-F6)/D6)*100) | N6: =IF(K6="","",K6/10000) | O6: =IF(OR(N6="",L6="",L6=0),"",(N6/L6)*100)
A7: M0 | B7: 200 | C7: 3 | K7: =IF(J7="","",J7*1000) | L7: =IF('1 - Mix Reference'!I5="","",'1 - Mix Reference'!I5) | M7: =IF(OR(D7="",F7=""),"",((D7-F7)/D7)*100) | N7: =IF(K7="","",K7/10000) | O7: =IF(OR(N7="",L7="",L7=0),"",(N7/L7)*100)
A8: M1 | B8: 200 | C8: 1 | K8: =IF(J8="","",J8*1000) | L8: =IF('1 - Mix Reference'!I6="","",'1 - Mix Reference'!I6) | M8: =IF(OR(D8="",F8=""),"",((D8-F8)/D8)*100) | N8: =IF(K8="","",K8/10000) | O8: =IF(OR(N8="",L8="",L8=0),"",(N8/L8)*100)
A9: M1 | B9: 200 | C9: 2 | K9: =IF(J9="","",J9*1000) | L9: =IF('1 - Mix Reference'!I6="","",'1 - Mix Reference'!I6) | M9: =IF(OR(D9="",F9=""),"",((D9-F9)/D9)*100) | N9: =IF(K9="","",K9/10000) | O9: =IF(OR(N9="",L9="",L9=0),"",(N9/L9)*100)
A10: M1 | B10: 200 | C10: 3 | K10: =IF(J10="","",J10*1000) | L10: =IF('1 - Mix Reference'!I6="","",'1 - Mix Reference'!I6) | M10: =IF(OR(D10="",F10=""),"",((D10-F10)/D10)*100) | N10: =IF(K10="","",K10/10000) | O10: =IF(OR(N10="",L10="",L10=0),"",(N10/L10)*100)
A11: M2 | B11: 200 | C11: 1 | K11: =IF(J11="","",J11*1000) | L11: =IF('1 - Mix Reference'!I7="","",'1 - Mix Reference'!I7) | M11: =IF(OR(D11="",F11=""),"",((D11-F11)/D11)*100) | N11: =IF(K11="","",K11/10000) | O11: =IF(OR(N11="",L11="",L11=0),"",(N11/L11)*100)
A12: M2 | B12: 200 | C12: 2 | K12: =IF(J12="","",J12*1000) | L12: =IF('1 - Mix Reference'!I7="","",'1 - Mix Reference'!I7) | M12: =IF(OR(D12="",F12=""),"",((D12-F12)/D12)*100) | N12: =IF(K12="","",K12/10000) | O12: =IF(OR(N12="",L12="",L12=0),"",(N12/L12)*100)
A13: M2 | B13: 200 | C13: 3 | K13: =IF(J13="","",J13*1000) | L13: =IF('1 - Mix Reference'!I7="","",'1 - Mix Reference'!I7) | M13: =IF(OR(D13="",F13=""),"",((D13-F13)/D13)*100) | N13: =IF(K13="","",K13/10000) | O13: =IF(OR(N13="",L13="",L13=0),"",(N13/L13)*100)
A14: M3 | B14: 200 | C14: 1 | K14: =IF(J14="","",J14*1000) | L14: =IF('1 - Mix Reference'!I8="","",'1 - Mix Reference'!I8) | M14: =IF(OR(D14="",F14=""),"",((D14-F14)/D14)*100) | N14: =IF(K14="","",K14/10000) | O14: =IF(OR(N14="",L14="",L14=0),"",(N14/L14)*100)
A15: M3 | B15: 200 | C15: 2 | K15: =IF(J15="","",J15*1000) | L15: =IF('1 - Mix Reference'!I8="","",'1 - Mix Reference'!I8) | M15: =IF(OR(D15="",F15=""),"",((D15-F15)/D15)*100) | N15: =IF(K15="","",K15/10000) | O15: =IF(OR(N15="",L15="",L15=0),"",(N15/L15)*100)
A16: M3 | B16: 200 | C16: 3 | K16: =IF(J16="","",J16*1000) | L16: =IF('1 - Mix Reference'!I8="","",'1 - Mix Reference'!I8) | M16: =IF(OR(D16="",F16=""),"",((D16-F16)/D16)*100) | N16: =IF(K16="","",K16/10000) | O16: =IF(OR(N16="",L16="",L16=0),"",(N16/L16)*100)
A17: M4 | B17: 200 | C17: 1 | K17: =IF(J17="","",J17*1000) | L17: =IF('1 - Mix Reference'!I9="","",'1 - Mix Reference'!I9) | M17: =IF(OR(D17="",F17=""),"",((D17-F17)/D17)*100) | N17: =IF(K17="","",K17/10000) | O17: =IF(OR(N17="",L17="",L17=0),"",(N17/L17)*100)
A18: M4 | B18: 200 | C18: 2 | K18: =IF(J18="","",J18*1000) | L18: =IF('1 - Mix Reference'!I9="","",'1 - Mix Reference'!I9) | M18: =IF(OR(D18="",F18=""),"",((D18-F18)/D18)*100) | N18: =IF(K18="","",K18/10000) | O18: =IF(OR(N18="",L18="",L18=0),"",(N18/L18)*100)
A19: M4 | B19: 200 | C19: 3 | K19: =IF(J19="","",J19*1000) | L19: =IF('1 - Mix Reference'!I9="","",'1 - Mix Reference'!I9) | M19: =IF(OR(D19="",F19=""),"",((D19-F19)/D19)*100) | N19: =IF(K19="","",K19/10000) | O19: =IF(OR(N19="",L19="",L19=0),"",(N19/L19)*100)
A20: M5 | B20: 200 | C20: 1 | K20: =IF(J20="","",J20*1000) | L20: =IF('1 - Mix Reference'!I10="","",'1 - Mix Reference'!I10) | M20: =IF(OR(D20="",F20=""),"",((D20-F20)/D20)*100) | N20: =IF(K20="","",K20/10000) | O20: =IF(OR(N20="",L20="",L20=0),"",(N20/L20)*100)
A21: M5 | B21: 200 | C21: 2 | K21: =IF(J21="","",J21*1000) | L21: =IF('1 - Mix Reference'!I10="","",'1 - Mix Reference'!I10) | M21: =IF(OR(D21="",F21=""),"",((D21-F21)/D21)*100) | N21: =IF(K21="","",K21/10000) | O21: =IF(OR(N21="",L21="",L21=0),"",(N21/L21)*100)
A22: M5 | B22: 200 | C22: 3 | K22: =IF(J22="","",J22*1000) | L22: =IF('1 - Mix Reference'!I10="","",'1 - Mix Reference'!I10) | M22: =IF(OR(D22="",F22=""),"",((D22-F22)/D22)*100) | N22: =IF(K22="","",K22/10000) | O22: =IF(OR(N22="",L22="",L22=0),"",(N22/L22)*100)
A23: M6 | B23: 200 | C23: 1 | K23: =IF(J23="","",J23*1000) | L23: =IF('1 - Mix Reference'!I11="","",'1 - Mix Reference'!I11) | M23: =IF(OR(D23="",F23=""),"",((D23-F23)/D23)*100) | N23: =IF(K23="","",K23/10000) | O23: =IF(OR(N23="",L23="",L23=0),"",(N23/L23)*100)
A24: M6 | B24: 200 | C24: 2 | K24: =IF(J24="","",J24*1000) | L24: =IF('1 - Mix Reference'!I11="","",'1 - Mix Reference'!I11) | M24: =IF(OR(D24="",F24=""),"",((D24-F24)/D24)*100) | N24: =IF(K24="","",K24/10000) | O24: =IF(OR(N24="",L24="",L24=0),"",(N24/L24)*100)
A25: M6 | B25: 200 | C25: 3 | K25: =IF(J25="","",J25*1000) | L25: =IF('1 - Mix Reference'!I11="","",'1 - Mix Reference'!I11) | M25: =IF(OR(D25="",F25=""),"",((D25-F25)/D25)*100) | N25: =IF(K25="","",K25/10000) | O25: =IF(OR(N25="",L25="",L25=0),"",(N25/L25)*100)
A26: M7 | B26: 200 | C26: 1 | K26: =IF(J26="","",J26*1000) | L26: =IF('1 - Mix Reference'!I12="","",'1 - Mix Reference'!I12) | M26: =IF(OR(D26="",F26=""),"",((D26-F26)/D26)*100) | N26: =IF(K26="","",K26/10000) | O26: =IF(OR(N26="",L26="",L26=0),"",(N26/L26)*100)
A27: M7 | B27: 200 | C27: 2 | K27: =IF(J27="","",J27*1000) | L27: =IF('1 - Mix Reference'!I12="","",'1 - Mix Reference'!I12) | M27: =IF(OR(D27="",F27=""),"",((D27-F27)/D27)*100) | N27: =IF(K27="","",K27/10000) | O27: =IF(OR(N27="",L27="",L27=0),"",(N27/L27)*100)
A28: M7 | B28: 200 | C28: 3 | K28: =IF(J28="","",J28*1000) | L28: =IF('1 - Mix Reference'!I12="","",'1 - Mix Reference'!I12) | M28: =IF(OR(D28="",F28=""),"",((D28-F28)/D28)*100) | N28: =IF(K28="","",K28/10000) | O28: =IF(OR(N28="",L28="",L28=0),"",(N28/L28)*100)
A29: M8 | B29: 200 | C29: 1 | K29: =IF(J29="","",J29*1000) | L29: =IF('1 - Mix Reference'!I13="","",'1 - Mix Reference'!I13) | M29: =IF(OR(D29="",F29=""),"",((D29-F29)/D29)*100) | N29: =IF(K29="","",K29/10000) | O29: =IF(OR(N29="",L29="",L29=0),"",(N29/L29)*100)
A30: M8 | B30: 200 | C30: 2 | K30: =IF(J30="","",J30*1000) | L30: =IF('1 - Mix Reference'!I13="","",'1 - Mix Reference'!I13) | M30: =IF(OR(D30="",F30=""),"",((D30-F30)/D30)*100) | N30: =IF(K30="","",K30/10000) | O30: =IF(OR(N30="",L30="",L30=0),"",(N30/L30)*100)
A31: M8 | B31: 200 | C31: 3 | K31: =IF(J31="","",J31*1000) | L31: =IF('1 - Mix Reference'!I13="","",'1 - Mix Reference'!I13) | M31: =IF(OR(D31="",F31=""),"",((D31-F31)/D31)*100) | N31: =IF(K31="","",K31/10000) | O31: =IF(OR(N31="",L31="",L31=0),"",(N31/L31)*100)
A32: M9 | B32: 200 | C32: 1 | K32: =IF(J32="","",J32*1000) | L32: =IF('1 - Mix Reference'!I14="","",'1 - Mix Reference'!I14) | M32: =IF(OR(D32="",F32=""),"",((D32-F32)/D32)*100) | N32: =IF(K32="","",K32/10000) | O32: =IF(OR(N32="",L32="",L32=0),"",(N32/L32)*100)
A33: M9 | B33: 200 | C33: 2 | K33: =IF(J33="","",J33*1000) | L33: =IF('1 - Mix Reference'!I14="","",'1 - Mix Reference'!I14) | M33: =IF(OR(D33="",F33=""),"",((D33-F33)/D33)*100) | N33: =IF(K33="","",K33/10000) | O33: =IF(OR(N33="",L33="",L33=0),"",(N33/L33)*100)
A34: M9 | B34: 200 | C34: 3 | K34: =IF(J34="","",J34*1000) | L34: =IF('1 - Mix Reference'!I14="","",'1 - Mix Reference'!I14) | M34: =IF(OR(D34="",F34=""),"",((D34-F34)/D34)*100) | N34: =IF(K34="","",K34/10000) | O34: =IF(OR(N34="",L34="",L34=0),"",(N34/L34)*100)
A35: M10 | B35: 200 | C35: 1 | K35: =IF(J35="","",J35*1000) | L35: =IF('1 - Mix Reference'!I15="","",'1 - Mix Reference'!I15) | M35: =IF(OR(D35="",F35=""),"",((D35-F35)/D35)*100) | N35: =IF(K35="","",K35/10000) | O35: =IF(OR(N35="",L35="",L35=0),"",(N35/L35)*100)
A36: M10 | B36: 200 | C36: 2 | K36: =IF(J36="","",J36*1000) | L36: =IF('1 - Mix Reference'!I15="","",'1 - Mix Reference'!I15) | M36: =IF(OR(D36="",F36=""),"",((D36-F36)/D36)*100) | N36: =IF(K36="","",K36/10000) | O36: =IF(OR(N36="",L36="",L36=0),"",(N36/L36)*100)
A37: M10 | B37: 200 | C37: 3 | K37: =IF(J37="","",J37*1000) | L37: =IF('1 - Mix Reference'!I15="","",'1 - Mix Reference'!I15) | M37: =IF(OR(D37="",F37=""),"",((D37-F37)/D37)*100) | N37: =IF(K37="","",K37/10000) | O37: =IF(OR(N37="",L37="",L37=0),"",(N37/L37)*100)
A38: M11 | B38: 200 | C38: 1 | K38: =IF(J38="","",J38*1000) | L38: =IF('1 - Mix Reference'!I16="","",'1 - Mix Reference'!I16) | M38: =IF(OR(D38="",F38=""),"",((D38-F38)/D38)*100) | N38: =IF(K38="","",K38/10000) | O38: =IF(OR(N38="",L38="",L38=0),"",(N38/L38)*100)
A39: M11 | B39: 200 | C39: 2 | K39: =IF(J39="","",J39*1000) | L39: =IF('1 - Mix Reference'!I16="","",'1 - Mix Reference'!I16) | M39: =IF(OR(D39="",F39=""),"",((D39-F39)/D39)*100) | N39: =IF(K39="","",K39/10000) | O39: =IF(OR(N39="",L39="",L39=0),"",(N39/L39)*100)
A40: M11 | B40: 200 | C40: 3 | K40: =IF(J40="","",J40*1000) | L40: =IF('1 - Mix Reference'!I16="","",'1 - Mix Reference'!I16) | M40: =IF(OR(D40="",F40=""),"",((D40-F40)/D40)*100) | N40: =IF(K40="","",K40/10000) | O40: =IF(OR(N40="",L40="",L40=0),"",(N40/L40)*100)
...

Sheet 3 - Charts & Curves
A1: SCGPC Fire Resistance Analysis — Graphical Charts & Temperature Curves
A2: Automated bar charts and curve diagrams, placed before the results summaries. They redraw as data is entered in Sheet 2. Chart source tables are below the charts (row 128 onwards). Grey N/A entries in tables 5–8 = data not entered yet (keeps curves from dropping to zero).
A4: CHART GROUP A: Curve diagrams — Residual strength (%) vs Temperature
A24: CHART GROUP B: Curve diagrams — Effect of SCBA replacement level at each temperature
A44: CHART GROUP C: Curve diagrams — Mass loss (%) vs Temperature
A64: CHART GROUP D: Bar charts — Comparison of all 12 mixes (clustered by temperature)
A104: CHART GROUP E: Key comparisons — Control vs key mix M9, and NaOH 4M vs 6M
A127: CHART SOURCE TABLES — formula-driven from Sheets 1, 2, 4 and 5 (do not edit)
A128: DATA TABLE 1: Residual Compressive Strength (%) Across Temperatures
A129: Mix ID | B129: SCBA (%) | C129: Molarity | D129: 200°C | E129: 400°C | F129: 600°C | G129: 800°C
A130: M0 | B130: ='1 - Mix Reference'!B5 -> 0 | C130: ='1 - Mix Reference'!C5 -> 4M | D130: ='4 - Residual Strength Summary'!D5 -> Data pending | E130: ='4 - Residual Strength Summary'!E5 -> Data pending | F130: ='4 - Residual Strength Summary'!F5 -> Data pending | G130: ='4 - Residual Strength Summary'!G5 -> Data pending
A131: M1 | B131: ='1 - Mix Reference'!B6 -> 5 | C131: ='1 - Mix Reference'!C6 -> 4M | D131: ='4 - Residual Strength Summary'!D6 -> Data pending | E131: ='4 - Residual Strength Summary'!E6 -> Data pending | F131: ='4 - Residual Strength Summary'!F6 -> Data pending | G131: ='4 - Residual Strength Summary'!G6 -> Data pending
A132: M2 | B132: ='1 - Mix Reference'!B7 -> 10 | C132: ='1 - Mix Reference'!C7 -> 4M | D132: ='4 - Residual Strength Summary'!D7 -> Data pending | E132: ='4 - Residual Strength Summary'!E7 -> Data pending | F132: ='4 - Residual Strength Summary'!F7 -> Data pending | G132: ='4 - Residual Strength Summary'!G7 -> Data pending
A133: M3 | B133: ='1 - Mix Reference'!B8 -> 15 | C133: ='1 - Mix Reference'!C8 -> 4M | D133: ='4 - Residual Strength Summary'!D8 -> Data pending | E133: ='4 - Residual Strength Summary'!E8 -> Data pending | F133: ='4 - Residual Strength Summary'!F8 -> Data pending | G133: ='4 - Residual Strength Summary'!G8 -> Data pending
A134: M4 | B134: ='1 - Mix Reference'!B9 -> 20 | C134: ='1 - Mix Reference'!C9 -> 4M | D134: ='4 - Residual Strength Summary'!D9 -> Data pending | E134: ='4 - Residual Strength Summary'!E9 -> Data pending | F134: ='4 - Residual Strength Summary'!F9 -> Data pending | G134: ='4 - Residual Strength Summary'!G9 -> Data pending
A135: M5 | B135: ='1 - Mix Reference'!B10 -> 25 | C135: ='1 - Mix Reference'!C10 -> 4M | D135: ='4 - Residual Strength Summary'!D10 -> Data pending | E135: ='4 - Residual Strength Summary'!E10 -> Data pending | F135: ='4 - Residual Strength Summary'!F10 -> Data pending | G135: ='4 - Residual Strength Summary'!G10 -> Data pending
A136: M6 | B136: ='1 - Mix Reference'!B11 -> 0 | C136: ='1 - Mix Reference'!C11 -> 6M | D136: ='4 - Residual Strength Summary'!D11 -> Data pending | E136: ='4 - Residual Strength Summary'!E11 -> Data pending | F136: ='4 - Residual Strength Summary'!F11 -> Data pending | G136: ='4 - Residual Strength Summary'!G11 -> Data pending
A137: M7 | B137: ='1 - Mix Reference'!B12 -> 5 | C137: ='1 - Mix Reference'!C12 -> 6M | D137: ='4 - Residual Strength Summary'!D12 -> Data pending | E137: ='4 - Residual Strength Summary'!E12 -> Data pending | F137: ='4 - Residual Strength Summary'!F12 -> Data pending | G137: ='4 - Residual Strength Summary'!G12 -> Data pending
A138: M8 | B138: ='1 - Mix Reference'!B13 -> 10 | C138: ='1 - Mix Reference'!C13 -> 6M | D138: ='4 - Residual Strength Summary'!D13 -> Data pending | E138: ='4 - Residual Strength Summary'!E13 -> Data pending | F138: ='4 - Residual Strength Summary'!F13 -> Data pending | G138: ='4 - Residual Strength Summary'!G13 -> Data pending
A139: M9 | B139: ='1 - Mix Reference'!B14 -> 15 | C139: ='1 - Mix Reference'!C14 -> 6M | D139: ='4 - Residual Strength Summary'!D14 -> Data pending | E139: ='4 - Residual Strength Summary'!E14 -> Data pending | F139: ='4 - Residual Strength Summary'!F14 -> Data pending | G139: ='4 - Residual Strength Summary'!G14 -> Data pending
A140: M10 | B140: ='1 - Mix Reference'!B15 -> 20 | C140: ='1 - Mix Reference'!C15 -> 6M | D140: ='4 - Residual Strength Summary'!D15 -> Data pending | E140: ='4 - Residual Strength Summary'!E15 -> Data pending | F140: ='4 - Residual Strength Summary'!F15 -> Data pending | G140: ='4 - Residual Strength Summary'!G15 -> Data pending
A141: M11 | B141: ='1 - Mix Reference'!B16 -> 25 | C141: ='1 - Mix Reference'!C16 -> 6M | D141: ='4 - Residual Strength Summary'!D16 -> Data pending | E141: ='4 - Residual Strength Summary'!E16 -> Data pending | F141: ='4 - Residual Strength Summary'!F16 -> Data pending | G141: ='4 - Residual Strength Summary'!G16 -> Data pending
A143: DATA TABLE 2: Mass Loss (%) Across Temperatures
A144: Mix ID | B144: SCBA (%) | C144: Molarity | D144: 200°C | E144: 400°C | F144: 600°C | G144: 800°C
A145: M0 | B145: ='1 - Mix Reference'!B5 -> 0 | C145: ='1 - Mix Reference'!C5 -> 4M | D145: ='5 - Mass Loss Summary'!D5 -> Data pending | E145: ='5 - Mass Loss Summary'!E5 -> Data pending | F145: ='5 - Mass Loss Summary'!F5 -> Data pending | G145: ='5 - Mass Loss Summary'!G5 -> Data pending
A146: M1 | B146: ='1 - Mix Reference'!B6 -> 5 | C146: ='1 - Mix Reference'!C6 -> 4M | D146: ='5 - Mass Loss Summary'!D6 -> Data pending | E146: ='5 - Mass Loss Summary'!E6 -> Data pending | F146: ='5 - Mass Loss Summary'!F6 -> Data pending | G146: ='5 - Mass Loss Summary'!G6 -> Data pending
A147: M2 | B147: ='1 - Mix Reference'!B7 -> 10 | C147: ='1 - Mix Reference'!C7 -> 4M | D147: ='5 - Mass Loss Summary'!D7 -> Data pending | E147: ='5 - Mass Loss Summary'!E7 -> Data pending | F147: ='5 - Mass Loss Summary'!F7 -> Data pending | G147: ='5 - Mass Loss Summary'!G7 -> Data pending
A148: M3 | B148: ='1 - Mix Reference'!B8 -> 15 | C148: ='1 - Mix Reference'!C8 -> 4M | D148: ='5 - Mass Loss Summary'!D8 -> Data pending | E148: ='5 - Mass Loss Summary'!E8 -> Data pending | F148: ='5 - Mass Loss Summary'!F8 -> Data pending | G148: ='5 - Mass Loss Summary'!G8 -> Data pending
A149: M4 | B149: ='1 - Mix Reference'!B9 -> 20 | C149: ='1 - Mix Reference'!C9 -> 4M | D149: ='5 - Mass Loss Summary'!D9 -> Data pending | E149: ='5 - Mass Loss Summary'!E9 -> Data pending | F149: ='5 - Mass Loss Summary'!F9 -> Data pending | G149: ='5 - Mass Loss Summary'!G9 -> Data pending
A150: M5 | B150: ='1 - Mix Reference'!B10 -> 25 | C150: ='1 - Mix Reference'!C10 -> 4M | D150: ='5 - Mass Loss Summary'!D10 -> Data pending | E150: ='5 - Mass Loss Summary'!E10 -> Data pending | F150: ='5 - Mass Loss Summary'!F10 -> Data pending | G150: ='5 - Mass Loss Summary'!G10 -> Data pending
A151: M6 | B151: ='1 - Mix Reference'!B11 -> 0 | C151: ='1 - Mix Reference'!C11 -> 6M | D151: ='5 - Mass Loss Summary'!D11 -> Data pending | E151: ='5 - Mass Loss Summary'!E11 -> Data pending | F151: ='5 - Mass Loss Summary'!F11 -> Data pending | G151: ='5 - Mass Loss Summary'!G11 -> Data pending
A152: M7 | B152: ='1 - Mix Reference'!B12 -> 5 | C152: ='1 - Mix Reference'!C12 -> 6M | D152: ='5 - Mass Loss Summary'!D12 -> Data pending | E152: ='5 - Mass Loss Summary'!E12 -> Data pending | F152: ='5 - Mass Loss Summary'!F12 -> Data pending | G152: ='5 - Mass Loss Summary'!G12 -> Data pending
A153: M8 | B153: ='1 - Mix Reference'!B13 -> 10 | C153: ='1 - Mix Reference'!C13 -> 6M | D153: ='5 - Mass Loss Summary'!D13 -> Data pending | E153: ='5 - Mass Loss Summary'!E13 -> Data pending | F153: ='5 - Mass Loss Summary'!F13 -> Data pending | G153: ='5 - Mass Loss Summary'!G13 -> Data pending
A154: M9 | B154: ='1 - Mix Reference'!B14 -> 15 | C154: ='1 - Mix Reference'!C14 -> 6M | D154: ='5 - Mass Loss Summary'!D14 -> Data pending | E154: ='5 - Mass Loss Summary'!E14 -> Data pending | F154: ='5 - Mass Loss Summary'!F14 -> Data pending | G154: ='5 - Mass Loss Summary'!G14 -> Data pending
A155: M10 | B155: ='1 - Mix Reference'!B15 -> 20 | C155: ='1 - Mix Reference'!C15 -> 6M | D155: ='5 - Mass Loss Summary'!D15 -> Data pending | E155: ='5 - Mass Loss Summary'!E15 -> Data pending | F155: ='5 - Mass Loss Summary'!F15 -> Data pending | G155: ='5 - Mass Loss Summary'!G15 -> Data pending
A156: M11 | B156: ='1 - Mix Reference'!B16 -> 25 | C156: ='1 - Mix Reference'!C16 -> 6M | D156: ='5 - Mass Loss Summary'!D16 -> Data pending | E156: ='5 - Mass Loss Summary'!E16 -> Data pending | F156: ='5 - Mass Loss Summary'!F16 -> Data pending | G156: ='5 - Mass Loss Summary'!G16 -> Data pending
A158: DATA TABLE 3: Residual Compressive Strength (MPa) — average of 3 replicates
A159: Mix ID | B159: SCBA (%) | C159: Molarity | D159: 200°C | E159: 400°C | F159: 600°C | G159: 800°C
A160: M0 | B160: ='1 - Mix Reference'!B5 -> 0 | C160: ='1 - Mix Reference'!C5 -> 4M | D160: =IF(COUNT('2 - Raw Data Entry'!N5:N7)=0,"Data pending",AVERAGE('2 - Raw Data Entry'!N5:N7)) -> Data pending | E160: =IF(COUNT('2 - Raw Data Entry'!N41:N43)=0,"Data pending",AVERAGE('2 - Raw Data Entry'!N41:N43)) -> Data pending | F160: =IF(COUNT('2 - Raw Data Entry'!N77:N79)=0,"Data pending",AVERAGE('2 - Raw Data Entry'!N77:N79)) -> Data pending | G160: =IF(COUNT('2 - Raw Data Entry'!N113:N115)=0,"Data pending",AVERAGE('2 - Raw Data Entry'!N113:N115)) -> Data pending
A161: M1 | B161: ='1 - Mix Reference'!B6 -> 5 | C161: ='1 - Mix Reference'!C6 -> 4M | D161: =IF(COUNT('2 - Raw Data Entry'!N8:N10)=0,"Data pending",AVERAGE('2 - Raw Data Entry'!N8:N10)) -> Data pending | E161: =IF(COUNT('2 - Raw Data Entry'!N44:N46)=0,"Data pending",AVERAGE('2 - Raw Data Entry'!N44:N46)) -> Data pending | F161: =IF(COUNT('2 - Raw Data Entry'!N80:N82)=0,"Data pending",AVERAGE('2 - Raw Data Entry'!N80:N82)) -> Data pending | G161: =IF(COUNT('2 - Raw Data Entry'!N116:N118)=0,"Data pending",AVERAGE('2 - Raw Data Entry'!N116:N118)) -> Data pending
...

Sheet 4 - Residual Strength Summary
A1: Residual Strength Summary — Average per Mix per Temperature
A2: Values are AVERAGE of 3 replicates. Residual Strength % = (Residual Compressive Strength / 28-Day Strength) × 100.
A4: Mix ID | B4: Series / Molarity | C4: SCBA (%) | D4: 200°C Residual Strength (%) | E4: 400°C Residual Strength (%) | F4: 600°C Residual Strength (%) | G4: 800°C Residual Strength (%) | H4: Mix Notes & Findings
A5: M0 | B5: 4M NaOH | C5: 0 | D5: =IF(COUNT('2 - Raw Data Entry'!O5:O7)=0,"Data pending",AVERAGE('2 - Raw Data Entry'!O5:O7)) -> Data pending | E5: =IF(COUNT('2 - Raw Data Entry'!O41:O43)=0,"Data pending",AVERAGE('2 - Raw Data Entry'!O41:O43)) -> Data pending | F5: =IF(COUNT('2 - Raw Data Entry'!O77:O79)=0,"Data pending",AVERAGE('2 - Raw Data Entry'!O77:O79)) -> Data pending | G5: =IF(COUNT('2 - Raw Data Entry'!O113:O115)=0,"Data pending",AVERAGE('2 - Raw Data Entry'!O113:O115)) -> Data pending | H5: Baseline — 0% SCBA, FA:GGBS 70:30, 4M NaOH
A6: M1 | B6: 4M NaOH | C6: 5 | D6: =IF(COUNT('2 - Raw Data Entry'!O8:O10)=0,"Data pending",AVERAGE('2 - Raw Data Entry'!O8:O10)) -> Data pending | E6: =IF(COUNT('2 - Raw Data Entry'!O44:O46)=0,"Data pending",AVERAGE('2 - Raw Data Entry'!O44:O46)) -> Data pending | F6: =IF(COUNT('2 - Raw Data Entry'!O80:O82)=0,"Data pending",AVERAGE('2 - Raw Data Entry'!O80:O82)) -> Data pending | G6: =IF(COUNT('2 - Raw Data Entry'!O116:O118)=0,"Data pending",AVERAGE('2 - Raw Data Entry'!O116:O118)) -> Data pending | H6: 5% SCBA replacement
A7: M2 | B7: 4M NaOH | C7: 10 | D7: =IF(COUNT('2 - Raw Data Entry'!O11:O13)=0,"Data pending",AVERAGE('2 - Raw Data Entry'!O11:O13)) -> Data pending | E7: =IF(COUNT('2 - Raw Data Entry'!O47:O49)=0,"Data pending",AVERAGE('2 - Raw Data Entry'!O47:O49)) -> Data pending | F7: =IF(COUNT('2 - Raw Data Entry'!O83:O85)=0,"Data pending",AVERAGE('2 - Raw Data Entry'!O83:O85)) -> Data pending | G7: =IF(COUNT('2 - Raw Data Entry'!O119:O121)=0,"Data pending",AVERAGE('2 - Raw Data Entry'!O119:O121)) -> Data pending | H7: 10% SCBA replacement
A8: M3 | B8: 4M NaOH | C8: 15 | D8: =IF(COUNT('2 - Raw Data Entry'!O14:O16)=0,"Data pending",AVERAGE('2 - Raw Data Entry'!O14:O16)) -> Data pending | E8: =IF(COUNT('2 - Raw Data Entry'!O50:O52)=0,"Data pending",AVERAGE('2 - Raw Data Entry'!O50:O52)) -> Data pending | F8: =IF(COUNT('2 - Raw Data Entry'!O86:O88)=0,"Data pending",AVERAGE('2 - Raw Data Entry'!O86:O88)) -> Data pending | G8: =IF(COUNT('2 - Raw Data Entry'!O122:O124)=0,"Data pending",AVERAGE('2 - Raw Data Entry'!O122:O124)) -> Data pending | H8: 15% SCBA replacement
A9: M4 | B9: 4M NaOH | C9: 20 | D9: =IF(COUNT('2 - Raw Data Entry'!O17:O19)=0,"Data pending",AVERAGE('2 - Raw Data Entry'!O17:O19)) -> Data pending | E9: =IF(COUNT('2 - Raw Data Entry'!O53:O55)=0,"Data pending",AVERAGE('2 - Raw Data Entry'!O53:O55)) -> Data pending | F9: =IF(COUNT('2 - Raw Data Entry'!O89:O91)=0,"Data pending",AVERAGE('2 - Raw Data Entry'!O89:O91)) -> Data pending | G9: =IF(COUNT('2 - Raw Data Entry'!O125:O127)=0,"Data pending",AVERAGE('2 - Raw Data Entry'!O125:O127)) -> Data pending | H9: 20% SCBA replacement
A10: M5 | B10: 4M NaOH | C10: 25 | D10: =IF(COUNT('2 - Raw Data Entry'!O20:O22)=0,"Data pending",AVERAGE('2 - Raw Data Entry'!O20:O22)) -> Data pending | E10: =IF(COUNT('2 - Raw Data Entry'!O56:O58)=0,"Data pending",AVERAGE('2 - Raw Data Entry'!O56:O58)) -> Data pending | F10: =IF(COUNT('2 - Raw Data Entry'!O92:O94)=0,"Data pending",AVERAGE('2 - Raw Data Entry'!O92:O94)) -> Data pending | G10: =IF(COUNT('2 - Raw Data Entry'!O128:O130)=0,"Data pending",AVERAGE('2 - Raw Data Entry'!O128:O130)) -> Data pending | H10: 25% SCBA upper bound — watch workability
A11: M6 | B11: 6M NaOH | C11: 0 | D11: =IF(COUNT('2 - Raw Data Entry'!O23:O25)=0,"Data pending",AVERAGE('2 - Raw Data Entry'!O23:O25)) -> Data pending | E11: =IF(COUNT('2 - Raw Data Entry'!O59:O61)=0,"Data pending",AVERAGE('2 - Raw Data Entry'!O59:O61)) -> Data pending | F11: =IF(COUNT('2 - Raw Data Entry'!O95:O97)=0,"Data pending",AVERAGE('2 - Raw Data Entry'!O95:O97)) -> Data pending | G11: =IF(COUNT('2 - Raw Data Entry'!O131:O133)=0,"Data pending",AVERAGE('2 - Raw Data Entry'!O131:O133)) -> Data pending | H11: Baseline — 0% SCBA, FA:GGBS 70:30, 6M NaOH
A12: M7 | B12: 6M NaOH | C12: 5 | D12: =IF(COUNT('2 - Raw Data Entry'!O26:O28)=0,"Data pending",AVERAGE('2 - Raw Data Entry'!O26:O28)) -> Data pending | E12: =IF(COUNT('2 - Raw Data Entry'!O62:O64)=0,"Data pending",AVERAGE('2 - Raw Data Entry'!O62:O64)) -> Data pending | F12: =IF(COUNT('2 - Raw Data Entry'!O98:O100)=0,"Data pending",AVERAGE('2 - Raw Data Entry'!O98:O100)) -> Data pending | G12: =IF(COUNT('2 - Raw Data Entry'!O134:O136)=0,"Data pending",AVERAGE('2 - Raw Data Entry'!O134:O136)) -> Data pending | H12: 5% SCBA replacement
A13: M8 | B13: 6M NaOH | C13: 10 | D13: =IF(COUNT('2 - Raw Data Entry'!O29:O31)=0,"Data pending",AVERAGE('2 - Raw Data Entry'!O29:O31)) -> Data pending | E13: =IF(COUNT('2 - Raw Data Entry'!O65:O67)=0,"Data pending",AVERAGE('2 - Raw Data Entry'!O65:O67)) -> Data pending | F13: =IF(COUNT('2 - Raw Data Entry'!O101:O103)=0,"Data pending",AVERAGE('2 - Raw Data Entry'!O101:O103)) -> Data pending | G13: =IF(COUNT('2 - Raw Data Entry'!O137:O139)=0,"Data pending",AVERAGE('2 - Raw Data Entry'!O137:O139)) -> Data pending | H13: 10% SCBA replacement
A14: M9 | B14: 6M NaOH | C14: 15 | D14: =IF(COUNT('2 - Raw Data Entry'!O32:O34)=0,"Data pending",AVERAGE('2 - Raw Data Entry'!O32:O34)) -> Data pending | E14: =IF(COUNT('2 - Raw Data Entry'!O68:O70)=0,"Data pending",AVERAGE('2 - Raw Data Entry'!O68:O70)) -> Data pending | F14: =IF(COUNT('2 - Raw Data Entry'!O104:O106)=0,"Data pending",AVERAGE('2 - Raw Data Entry'!O104:O106)) -> Data pending | G14: =IF(COUNT('2 - Raw Data Entry'!O140:O142)=0,"Data pending",AVERAGE('2 - Raw Data Entry'!O140:O142)) -> Data pending | H14: 15% SCBA — likely optimum mix
A15: M10 | B15: 6M NaOH | C15: 20 | D15: =IF(COUNT('2 - Raw Data Entry'!O35:O37)=0,"Data pending",AVERAGE('2 - Raw Data Entry'!O35:O37)) -> Data pending | E15: =IF(COUNT('2 - Raw Data Entry'!O71:O73)=0,"Data pending",AVERAGE('2 - Raw Data Entry'!O71:O73)) -> Data pending | F15: =IF(COUNT('2 - Raw Data Entry'!O107:O109)=0,"Data pending",AVERAGE('2 - Raw Data Entry'!O107:O109)) -> Data pending | G15: =IF(COUNT('2 - Raw Data Entry'!O143:O145)=0,"Data pending",AVERAGE('2 - Raw Data Entry'!O143:O145)) -> Data pending | H15: 20% SCBA replacement
A16: M11 | B16: 6M NaOH | C16: 25 | D16: =IF(COUNT('2 - Raw Data Entry'!O38:O40)=0,"Data pending",AVERAGE('2 - Raw Data Entry'!O38:O40)) -> Data pending | E16: =IF(COUNT('2 - Raw Data Entry'!O74:O76)=0,"Data pending",AVERAGE('2 - Raw Data Entry'!O74:O76)) -> Data pending | F16: =IF(COUNT('2 - Raw Data Entry'!O110:O112)=0,"Data pending",AVERAGE('2 - Raw Data Entry'!O110:O112)) -> Data pending | G16: =IF(COUNT('2 - Raw Data Entry'!O146:O148)=0,"Data pending",AVERAGE('2 - Raw Data Entry'!O146:O148)) -> Data pending | H16: 25% SCBA upper bound — watch workability

Sheet 5 - Mass Loss Summary
A1: Mass Loss Summary — Average per Mix per Temperature
A2: Mass Loss % = ((Pre-fire mass − Post-fire mass) ÷ Pre-fire mass) × 100. Values are average of 3 replicates.
A4: Mix ID | B4: Series / Molarity | C4: SCBA (%) | D4: 200°C Mass Loss (%) | E4: 400°C Mass Loss (%) | F4: 600°C Mass Loss (%) | G4: 800°C Mass Loss (%) | H4: Mix Notes & Observations
A5: M0 | B5: 4M NaOH | C5: 0 | D5: =IF(COUNT('2 - Raw Data Entry'!M5:M7)=0,"Data pending",AVERAGE('2 - Raw Data Entry'!M5:M7)) -> Data pending | E5: =IF(COUNT('2 - Raw Data Entry'!M41:M43)=0,"Data pending",AVERAGE('2 - Raw Data Entry'!M41:M43)) -> Data pending | F5: =IF(COUNT('2 - Raw Data Entry'!M77:M79)=0,"Data pending",AVERAGE('2 - Raw Data Entry'!M77:M79)) -> Data pending | G5: =IF(COUNT('2 - Raw Data Entry'!M113:M115)=0,"Data pending",AVERAGE('2 - Raw Data Entry'!M113:M115)) -> Data pending | H5: Baseline — 0% SCBA, FA:GGBS 70:30, 4M NaOH
A6: M1 | B6: 4M NaOH | C6: 5 | D6: =IF(COUNT('2 - Raw Data Entry'!M8:M10)=0,"Data pending",AVERAGE('2 - Raw Data Entry'!M8:M10)) -> Data pending | E6: =IF(COUNT('2 - Raw Data Entry'!M44:M46)=0,"Data pending",AVERAGE('2 - Raw Data Entry'!M44:M46)) -> Data pending | F6: =IF(COUNT('2 - Raw Data Entry'!M80:M82)=0,"Data pending",AVERAGE('2 - Raw Data Entry'!M80:M82)) -> Data pending | G6: =IF(COUNT('2 - Raw Data Entry'!M116:M118)=0,"Data pending",AVERAGE('2 - Raw Data Entry'!M116:M118)) -> Data pending | H6: 5% SCBA replacement
A7: M2 | B7: 4M NaOH | C7: 10 | D7: =IF(COUNT('2 - Raw Data Entry'!M11:M13)=0,"Data pending",AVERAGE('2 - Raw Data Entry'!M11:M13)) -> Data pending | E7: =IF(COUNT('2 - Raw Data Entry'!M47:M49)=0,"Data pending",AVERAGE('2 - Raw Data Entry'!M47:M49)) -> Data pending | F7: =IF(COUNT('2 - Raw Data Entry'!M83:M85)=0,"Data pending",AVERAGE('2 - Raw Data Entry'!M83:M85)) -> Data pending | G7: =IF(COUNT('2 - Raw Data Entry'!M119:M121)=0,"Data pending",AVERAGE('2 - Raw Data Entry'!M119:M121)) -> Data pending | H7: 10% SCBA replacement
A8: M3 | B8: 4M NaOH | C8: 15 | D8: =IF(COUNT('2 - Raw Data Entry'!M14:M16)=0,"Data pending",AVERAGE('2 - Raw Data Entry'!M14:M16)) -> Data pending | E8: =IF(COUNT('2 - Raw Data Entry'!M50:M52)=0,"Data pending",AVERAGE('2 - Raw Data Entry'!M50:M52)) -> Data pending | F8: =IF(COUNT('2 - Raw Data Entry'!M86:M88)=0,"Data pending",AVERAGE('2 - Raw Data Entry'!M86:M88)) -> Data pending | G8: =IF(COUNT('2 - Raw Data Entry'!M122:M124)=0,"Data pending",AVERAGE('2 - Raw Data Entry'!M122:M124)) -> Data pending | H8: 15% SCBA replacement
A9: M4 | B9: 4M NaOH | C9: 20 | D9: =IF(COUNT('2 - Raw Data Entry'!M17:M19)=0,"Data pending",AVERAGE('2 - Raw Data Entry'!M17:M19)) -> Data pending | E9: =IF(COUNT('2 - Raw Data Entry'!M53:M55)=0,"Data pending",AVERAGE('2 - Raw Data Entry'!M53:M55)) -> Data pending | F9: =IF(COUNT('2 - Raw Data Entry'!M89:M91)=0,"Data pending",AVERAGE('2 - Raw Data Entry'!M89:M91)) -> Data pending | G9: =IF(COUNT('2 - Raw Data Entry'!M125:M127)=0,"Data pending",AVERAGE('2 - Raw Data Entry'!M125:M127)) -> Data pending | H9: 20% SCBA replacement
A10: M5 | B10: 4M NaOH | C10: 25 | D10: =IF(COUNT('2 - Raw Data Entry'!M20:M22)=0,"Data pending",AVERAGE('2 - Raw Data Entry'!M20:M22)) -> Data pending | E10: =IF(COUNT('2 - Raw Data Entry'!M56:M58)=0,"Data pending",AVERAGE('2 - Raw Data Entry'!M56:M58)) -> Data pending | F10: =IF(COUNT('2 - Raw Data Entry'!M92:M94)=0,"Data pending",AVERAGE('2 - Raw Data Entry'!M92:M94)) -> Data pending | G10: =IF(COUNT('2 - Raw Data Entry'!M128:M130)=0,"Data pending",AVERAGE('2 - Raw Data Entry'!M128:M130)) -> Data pending | H10: 25% SCBA upper bound — watch workability
A11: M6 | B11: 6M NaOH | C11: 0 | D11: =IF(COUNT('2 - Raw Data Entry'!M23:M25)=0,"Data pending",AVERAGE('2 - Raw Data Entry'!M23:M25)) -> Data pending | E11: =IF(COUNT('2 - Raw Data Entry'!M59:M61)=0,"Data pending",AVERAGE('2 - Raw Data Entry'!M59:M61)) -> Data pending | F11: =IF(COUNT('2 - Raw Data Entry'!M95:M97)=0,"Data pending",AVERAGE('2 - Raw Data Entry'!M95:M97)) -> Data pending | G11: =IF(COUNT('2 - Raw Data Entry'!M131:M133)=0,"Data pending",AVERAGE('2 - Raw Data Entry'!M131:M133)) -> Data pending | H11: Baseline — 0% SCBA, FA:GGBS 70:30, 6M NaOH
A12: M7 | B12: 6M NaOH | C12: 5 | D12: =IF(COUNT('2 - Raw Data Entry'!M26:M28)=0,"Data pending",AVERAGE('2 - Raw Data Entry'!M26:M28)) -> Data pending | E12: =IF(COUNT('2 - Raw Data Entry'!M62:M64)=0,"Data pending",AVERAGE('2 - Raw Data Entry'!M62:M64)) -> Data pending | F12: =IF(COUNT('2 - Raw Data Entry'!M98:M100)=0,"Data pending",AVERAGE('2 - Raw Data Entry'!M98:M100)) -> Data pending | G12: =IF(COUNT('2 - Raw Data Entry'!M134:M136)=0,"Data pending",AVERAGE('2 - Raw Data Entry'!M134:M136)) -> Data pending | H12: 5% SCBA replacement
A13: M8 | B13: 6M NaOH | C13: 10 | D13: =IF(COUNT('2 - Raw Data Entry'!M29:M31)=0,"Data pending",AVERAGE('2 - Raw Data Entry'!M29:M31)) -> Data pending | E13: =IF(COUNT('2 - Raw Data Entry'!M65:M67)=0,"Data pending",AVERAGE('2 - Raw Data Entry'!M65:M67)) -> Data pending | F13: =IF(COUNT('2 - Raw Data Entry'!M101:M103)=0,"Data pending",AVERAGE('2 - Raw Data Entry'!M101:M103)) -> Data pending | G13: =IF(COUNT('2 - Raw Data Entry'!M137:M139)=0,"Data pending",AVERAGE('2 - Raw Data Entry'!M137:M139)) -> Data pending | H13: 10% SCBA replacement
A14: M9 | B14: 6M NaOH | C14: 15 | D14: =IF(COUNT('2 - Raw Data Entry'!M32:M34)=0,"Data pending",AVERAGE('2 - Raw Data Entry'!M32:M34)) -> Data pending | E14: =IF(COUNT('2 - Raw Data Entry'!M68:M70)=0,"Data pending",AVERAGE('2 - Raw Data Entry'!M68:M70)) -> Data pending | F14: =IF(COUNT('2 - Raw Data Entry'!M104:M106)=0,"Data pending",AVERAGE('2 - Raw Data Entry'!M104:M106)) -> Data pending | G14: =IF(COUNT('2 - Raw Data Entry'!M140:M142)=0,"Data pending",AVERAGE('2 - Raw Data Entry'!M140:M142)) -> Data pending | H14: 15% SCBA — likely optimum mix
A15: M10 | B15: 6M NaOH | C15: 20 | D15: =IF(COUNT('2 - Raw Data Entry'!M35:M37)=0,"Data pending",AVERAGE('2 - Raw Data Entry'!M35:M37)) -> Data pending | E15: =IF(COUNT('2 - Raw Data Entry'!M71:M73)=0,"Data pending",AVERAGE('2 - Raw Data Entry'!M71:M73)) -> Data pending | F15: =IF(COUNT('2 - Raw Data Entry'!M107:M109)=0,"Data pending",AVERAGE('2 - Raw Data Entry'!M107:M109)) -> Data pending | G15: =IF(COUNT('2 - Raw Data Entry'!M143:M145)=0,"Data pending",AVERAGE('2 - Raw Data Entry'!M143:M145)) -> Data pending | H15: 20% SCBA replacement
A16: M11 | B16: 6M NaOH | C16: 25 | D16: =IF(COUNT('2 - Raw Data Entry'!M38:M40)=0,"Data pending",AVERAGE('2 - Raw Data Entry'!M38:M40)) -> Data pending | E16: =IF(COUNT('2 - Raw Data Entry'!M74:M76)=0,"Data pending",AVERAGE('2 - Raw Data Entry'!M74:M76)) -> Data pending | F16: =IF(COUNT('2 - Raw Data Entry'!M110:M112)=0,"Data pending",AVERAGE('2 - Raw Data Entry'!M110:M112)) -> Data pending | G16: =IF(COUNT('2 - Raw Data Entry'!M146:M148)=0,"Data pending",AVERAGE('2 - Raw Data Entry'!M146:M148)) -> Data pending | H16: 25% SCBA upper bound — watch workability

Sheet 6 - Visual Observations Log
A1: Visual Observations Log — Post-Fire Physical Appearance
A2: Colour Guide: White/Grey = mild heating (200°C) | Brown/Reddish ≈ 400°C | Dark grey/Black ≥ 600°C | Light pink/buff ≈ 800°C. Record for every specimen.
A4: Specimen Label (Mix-Temp-Rep) | B4: Mix ID | C4: Temperature (°C) | D4: Replicate | E4: Series Category | F4: Colour Description | G4: Surface Cracking (None/Minor/Major) | H4: Spalling Assessment (None/Partial/Severe) | I4: Additional Morphological Notes
A5: M0-200-1 | B5: M0 | C5: 200 | D5: 1 | E5: 4M Series (Control)
A6: M0-200-2 | B6: M0 | C6: 200 | D6: 2 | E6: 4M Series (Control)
A7: M0-200-3 | B7: M0 | C7: 200 | D7: 3 | E7: 4M Series (Control)
A8: M1-200-1 | B8: M1 | C8: 200 | D8: 1 | E8: 4M Series
A9: M1-200-2 | B9: M1 | C9: 200 | D9: 2 | E9: 4M Series
A10: M1-200-3 | B10: M1 | C10: 200 | D10: 3 | E10: 4M Series
A11: M2-200-1 | B11: M2 | C11: 200 | D11: 1 | E11: 4M Series
A12: M2-200-2 | B12: M2 | C12: 200 | D12: 2 | E12: 4M Series
A13: M2-200-3 | B13: M2 | C13: 200 | D13: 3 | E13: 4M Series
A14: M3-200-1 | B14: M3 | C14: 200 | D14: 1 | E14: 4M Series
A15: M3-200-2 | B15: M3 | C15: 200 | D15: 2 | E15: 4M Series
A16: M3-200-3 | B16: M3 | C16: 200 | D16: 3 | E16: 4M Series
... A148: M11-800-3 | B148: M11 | C148: 800 | D148: 3 | E148: 6M Series

Sheet 7 - Schedule & Checklist
A1: Testing Schedule & Pre-Test Quality Checklist — Weeks 14–16
A3: Week | B3: Temperature Batches | C3: Specimen Count | D3: Task Description & Protocol | E3: Responsible Batch | F3: Completed? (Y/N)
A4: Week 14 | B4: 200°C Batch | C4: 36 cubes (12 mixes × 3 reps) | D4: Run 200°C first. Heating rate 5–10°C/min, hold 2 hours. Allow natural air cooling. Weigh, photograph, test residual CTM strength. Record all data. | E4: B.Tech Batch 2
A5: Week 14 | B5: 400°C Batch | C5: 36 cubes (12 mixes × 3 reps) | D5: Moderate fire scenario. Hold at 400°C for 2 hours. Cool naturally to room temperature. Weigh, inspect colour change, test CTM. | E5: B.Tech Batch 2
A6: Week 15 | B6: 600°C Batch | C6: 36 cubes (12 mixes × 3 reps) | D6: Severe fire scenario — phase changes. Expect visible colour shifts and microcracking. Allow extended natural cooling. Test residual strength. | E6: B.Tech Batch 2
A7: Week 16 | B7: 800°C Batch | C7: 36 cubes (12 mixes × 3 reps) | D7: Extreme fire exposure — structural assessment. Spalling and significant mass loss likely. Ensure ventilation. Hand over full dataset to M.Tech student. | E7: B.Tech Batch 2
A10: PRE-TEST VERIFICATION CHECKLIST
A11: ☐ | B11: Laboratory Blockout | C11: Furnace booking confirmed for all 3 testing weeks (Weeks 14, 15, and 16) | F11: Pending
A12: ☐ | B12: Data Prerequisite | C12: Original 28-day compressive strength values received from M.Tech student (for all 12 mixes) | F12: Pending
A13: ☐ | B13: Specimen Verification | C13: All 144 concrete cubes received and verified from casting team | F13: Pending
A14: ☐ | B14: Specimen Labelling | C14: All cubes clearly labelled: Mix ID – Temperature – Replicate number (e.g., M9-600-3) | F14: Pending
A15: ☐ | B15: Mass Measurement | C15: High-precision digital balance available, cleaned, and calibrated | F15: Pending
A16: ☐ | B16: Strength Testing | C16: CTM (Compression Testing Machine) calibrated with loading rate set to 2.5 kN/s | F16: Pending
A17: ☐ | B17: Laboratory Safety | C17: Heat-resistant safety gloves, tongs, and protective face shields available | F17: Pending
A18: ☐ | B18: Hazard Mitigation | C18: Laboratory exhaust and ventilation system verified operational for 600°C and 800°C runs | F18: Pending
A19: ☐ | B19: Visual Evidence | C19: High-resolution camera/phone prepared for pre-fire, post-fire, and failure mode documentation | F19: Pending
A20: ☐ | B20: Thermal Shock Prevention | C20: CRITICAL SAFETY RULE: Understood that specimens must NEVER be quenched in water (air cooling only) | F20: Pending
